<?xml version="1.0" ?>
<!-- =================================================================================== -->
<!-- |    This document was autogenerated by xacro from medsnake.xacro                 | -->
<!-- |    EDITING THIS FILE BY HAND IS NOT RECOMMENDED                                 | -->
<!-- =================================================================================== -->
<robot name="manipulator">
  <material name="white">
    <color rgba="1 1 1 1"/>
  </material>
  <material name="blue">
    <color rgba="0 0 .8 1"/>
  </material>
  <material name="yellow">
    <color rgba="1 1 0 1"/>
  </material>
  <material name="green">
    <color rgba="0 1 0 1"/>
  </material>
  <material name="orange">
    <color rgba="0.255 0.165 0 1"/>
  </material>
  <material name="red">
    <color rgba="1 0 0 1"/>
  </material>
  <link name="base_link">
    <visual>
      <geometry>
        <mesh filename="package://medsnake_sim/meshModel/base_part.STL" scale="0.001 0.001 0.001"/>
      </geometry>
      <origin rpy="1.5707963 0 -1.5707963" xyz="0.822 0.315 -0.22"/>
      <material name="blue"/>
    </visual>
  </link>
  <joint name="joint_inner" type="prismatic">
    <parent link="base_link"/>
    <child link="link_inner"/>
    <origin rpy="1.5707963 0 1.5707963" xyz="0.1 0 0.04"/>
    <limit effort="1000" lower="0" upper="0.35000000000000003" velocity="180"/>
    <axis xyz="0 0 1"/>
  </joint>
  <link name="link_inner">
    <inertial>
      <origin rpy="0 0 0" xyz="0 -0.016 0.161"/>
      <mass value="7.7"/>
      <inertia ixx="0.06718763333333333" ixy="0" ixz="0" iyy="0.06653056666666667" iyz="0" izz="0.0006570666666666666"/>
    </inertial>
    <visual>
      <geometry>
        <mesh filename="package://medsnake_sim/meshModel/inner_part.STL" scale="0.001 0.001 0.001"/>
      </geometry>
      <origin rpy="0 3.1415926 0" xyz="0.315 -0.26 0.732"/>
      <material name="red"/>
    </visual>
  </link>
  <joint name="joint_outer" type="prismatic">
    <parent link="base_link"/>
    <child link="link_outer"/>
    <origin rpy="1.5707963 0 1.5707963" xyz="0.2 0 0.04"/>
    <limit effort="1000" lower="0" upper="0.35000000000000003" velocity="180"/>
    <axis xyz="0 0 1"/>
  </joint>
  <link name="link_outer">
    <inertial>
      <origin rpy="1.5707963 0 1.5707963" xyz="0 -0.016 0.161"/>
      <mass value="7.7"/>
      <inertia ixx="0.06718763333333333" ixy="0" ixz="0" iyy="0.06653056666666667" iyz="0" izz="0.0006570666666666666"/>
    </inertial>
    <visual>
      <geometry>
        <mesh filename="package://medsnake_sim/meshModel/outer_part.STL" scale="0.001 0.001 0.001"/>
      </geometry>
      <origin rpy="0 3.1415926 0" xyz="0.315 -0.26 0.662"/>
      <material name="green"/>
    </visual>
  </link>
  <joint name="joint_snake" type="fixed">
    <parent link="link_outer"/>
    <child link="link_0"/>
    <origin rpy="0 0 0" xyz="0 0 0.12"/>
    <limit effort="1000" lower="0" upper="0.35000000000000003" velocity="180"/>
    <axis xyz="0 0 1"/>
  </joint>
  <link name="link_0">
    <visual>
      <geometry>
        <cylinder length="0.2" radius="0.01"/>
      </geometry>
      <origin rpy="0 0 0" xyz="0 0 0.1"/>
      <material name="yellow"/>
    </visual>
    <collision>
      <geometry>
        <cylinder length="0.2" radius="0.01"/>
      </geometry>
      <origin rpy="0 0 0" xyz="0 0 0.1"/>
    </collision>
  </link>
  <link name="link_30">
    <visual>
      <geometry>
        <cylinder length="0.02" radius="0.01"/>
      </geometry>
      <origin rpy="0 0 0" xyz="0 0 0.01"/>
      <material name="yellow"/>
    </visual>
    <collision>
      <geometry>
        <cylinder length="0.02" radius="0.01"/>
      </geometry>
      <origin rpy="0 0 0" xyz="0 0 0.01"/>
    </collision>
  </link>
  <joint name="balljoint_30_0" type="revolute">
    <parent link="link_29"/>
    <child link="zero_link_30_0"/>
    <origin rpy="0 0 0" xyz="0 0 0.02"/>
    <axis xyz="1 0 0"/>
    <limit effort="1000.0" lower="-0.78" upper="0.78" velocity="0.5"/>
  </joint>
  <link name="zero_link_30_0">
    <visual>
      <geometry>
        <cylinder length="0" radius="0"/>
      </geometry>
      <origin rpy="0 0 0" xyz="0 0 0"/>
    </visual>
  </link>
  <joint name="balljoint_30_1" type="revolute">
    <parent link="zero_link_30_0"/>
    <child link="zero_link_30_1"/>
    <origin rpy="0 0 0" xyz="0 0 0"/>
    <axis xyz="0 1 0"/>
    <limit effort="1000.0" lower="-0.78" upper="0.78" velocity="0.5"/>
  </joint>
  <link name="zero_link_30_1">
    <visual>
      <geometry>
        <cylinder length="0" radius="0"/>
      </geometry>
      <origin rpy="0 0 0" xyz="0 0 0"/>
    </visual>
  </link>
  <joint name="balljoint_30_2" type="revolute">
    <parent link="zero_link_30_1"/>
    <child link="link_30"/>
    <origin rpy="0 0 0" xyz="0 0 0"/>
    <axis xyz="0 0 1"/>
    <limit effort="1000.0" lower="-0.78" upper="0.78" velocity="0.5"/>
  </joint>
  <link name="link_29">
    <visual>
      <geometry>
        <cylinder length="0.02" radius="0.01"/>
      </geometry>
      <origin rpy="0 0 0" xyz="0 0 0.01"/>
      <material name="yellow"/>
    </visual>
    <collision>
      <geometry>
        <cylinder length="0.02" radius="0.01"/>
      </geometry>
      <origin rpy="0 0 0" xyz="0 0 0.01"/>
    </collision>
  </link>
  <joint name="balljoint_29_0" type="revolute">
    <parent link="link_28"/>
    <child link="zero_link_29_0"/>
    <origin rpy="0 0 0" xyz="0 0 0.02"/>
    <axis xyz="1 0 0"/>
    <limit effort="1000.0" lower="-0.78" upper="0.78" velocity="0.5"/>
  </joint>
  <link name="zero_link_29_0">
    <visual>
      <geometry>
        <cylinder length="0" radius="0"/>
      </geometry>
      <origin rpy="0 0 0" xyz="0 0 0"/>
    </visual>
  </link>
  <joint name="balljoint_29_1" type="revolute">
    <parent link="zero_link_29_0"/>
    <child link="zero_link_29_1"/>
    <origin rpy="0 0 0" xyz="0 0 0"/>
    <axis xyz="0 1 0"/>
    <limit effort="1000.0" lower="-0.78" upper="0.78" velocity="0.5"/>
  </joint>
  <link name="zero_link_29_1">
    <visual>
      <geometry>
        <cylinder length="0" radius="0"/>
      </geometry>
      <origin rpy="0 0 0" xyz="0 0 0"/>
    </visual>
  </link>
  <joint name="balljoint_29_2" type="revolute">
    <parent link="zero_link_29_1"/>
    <child link="link_29"/>
    <origin rpy="0 0 0" xyz="0 0 0"/>
    <axis xyz="0 0 1"/>
    <limit effort="1000.0" lower="-0.78" upper="0.78" velocity="0.5"/>
  </joint>
  <link name="link_28">
    <visual>
      <geometry>
        <cylinder length="0.02" radius="0.01"/>
      </geometry>
      <origin rpy="0 0 0" xyz="0 0 0.01"/>
      <material name="yellow"/>
    </visual>
    <collision>
      <geometry>
        <cylinder length="0.02" radius="0.01"/>
      </geometry>
      <origin rpy="0 0 0" xyz="0 0 0.01"/>
    </collision>
  </link>
  <joint name="balljoint_28_0" type="revolute">
    <parent link="link_27"/>
    <child link="zero_link_28_0"/>
    <origin rpy="0 0 0" xyz="0 0 0.02"/>
    <axis xyz="1 0 0"/>
    <limit effort="1000.0" lower="-0.78" upper="0.78" velocity="0.5"/>
  </joint>
  <link name="zero_link_28_0">
    <visual>
      <geometry>
        <cylinder length="0" radius="0"/>
      </geometry>
      <origin rpy="0 0 0" xyz="0 0 0"/>
    </visual>
  </link>
  <joint name="balljoint_28_1" type="revolute">
    <parent link="zero_link_28_0"/>
    <child link="zero_link_28_1"/>
    <origin rpy="0 0 0" xyz="0 0 0"/>
    <axis xyz="0 1 0"/>
    <limit effort="1000.0" lower="-0.78" upper="0.78" velocity="0.5"/>
  </joint>
  <link name="zero_link_28_1">
    <visual>
      <geometry>
        <cylinder length="0" radius="0"/>
      </geometry>
      <origin rpy="0 0 0" xyz="0 0 0"/>
    </visual>
  </link>
  <joint name="balljoint_28_2" type="revolute">
    <parent link="zero_link_28_1"/>
    <child link="link_28"/>
    <origin rpy="0 0 0" xyz="0 0 0"/>
    <axis xyz="0 0 1"/>
    <limit effort="1000.0" lower="-0.78" upper="0.78" velocity="0.5"/>
  </joint>
  <link name="link_27">
    <visual>
      <geometry>
        <cylinder length="0.02" radius="0.01"/>
      </geometry>
      <origin rpy="0 0 0" xyz="0 0 0.01"/>
      <material name="yellow"/>
    </visual>
    <collision>
      <geometry>
        <cylinder length="0.02" radius="0.01"/>
      </geometry>
      <origin rpy="0 0 0" xyz="0 0 0.01"/>
    </collision>
  </link>
  <joint name="balljoint_27_0" type="revolute">
    <parent link="link_26"/>
    <child link="zero_link_27_0"/>
    <origin rpy="0 0 0" xyz="0 0 0.02"/>
    <axis xyz="1 0 0"/>
    <limit effort="1000.0" lower="-0.78" upper="0.78" velocity="0.5"/>
  </joint>
  <link name="zero_link_27_0">
    <visual>
      <geometry>
        <cylinder length="0" radius="0"/>
      </geometry>
      <origin rpy="0 0 0" xyz="0 0 0"/>
    </visual>
  </link>
  <joint name="balljoint_27_1" type="revolute">
    <parent link="zero_link_27_0"/>
    <child link="zero_link_27_1"/>
    <origin rpy="0 0 0" xyz="0 0 0"/>
    <axis xyz="0 1 0"/>
    <limit effort="1000.0" lower="-0.78" upper="0.78" velocity="0.5"/>
  </joint>
  <link name="zero_link_27_1">
    <visual>
      <geometry>
        <cylinder length="0" radius="0"/>
      </geometry>
      <origin rpy="0 0 0" xyz="0 0 0"/>
    </visual>
  </link>
  <joint name="balljoint_27_2" type="revolute">
    <parent link="zero_link_27_1"/>
    <child link="link_27"/>
    <origin rpy="0 0 0" xyz="0 0 0"/>
    <axis xyz="0 0 1"/>
    <limit effort="1000.0" lower="-0.78" upper="0.78" velocity="0.5"/>
  </joint>
  <link name="link_26">
    <visual>
      <geometry>
        <cylinder length="0.02" radius="0.01"/>
      </geometry>
      <origin rpy="0 0 0" xyz="0 0 0.01"/>
      <material name="yellow"/>
    </visual>
    <collision>
      <geometry>
        <cylinder length="0.02" radius="0.01"/>
      </geometry>
      <origin rpy="0 0 0" xyz="0 0 0.01"/>
    </collision>
  </link>
  <joint name="balljoint_26_0" type="revolute">
    <parent link="link_25"/>
    <child link="zero_link_26_0"/>
    <origin rpy="0 0 0" xyz="0 0 0.02"/>
    <axis xyz="1 0 0"/>
    <limit effort="1000.0" lower="-0.78" upper="0.78" velocity="0.5"/>
  </joint>
  <link name="zero_link_26_0">
    <visual>
      <geometry>
        <cylinder length="0" radius="0"/>
      </geometry>
      <origin rpy="0 0 0" xyz="0 0 0"/>
    </visual>
  </link>
  <joint name="balljoint_26_1" type="revolute">
    <parent link="zero_link_26_0"/>
    <child link="zero_link_26_1"/>
    <origin rpy="0 0 0" xyz="0 0 0"/>
    <axis xyz="0 1 0"/>
    <limit effort="1000.0" lower="-0.78" upper="0.78" velocity="0.5"/>
  </joint>
  <link name="zero_link_26_1">
    <visual>
      <geometry>
        <cylinder length="0" radius="0"/>
      </geometry>
      <origin rpy="0 0 0" xyz="0 0 0"/>
    </visual>
  </link>
  <joint name="balljoint_26_2" type="revolute">
    <parent link="zero_link_26_1"/>
    <child link="link_26"/>
    <origin rpy="0 0 0" xyz="0 0 0"/>
    <axis xyz="0 0 1"/>
    <limit effort="1000.0" lower="-0.78" upper="0.78" velocity="0.5"/>
  </joint>
  <link name="link_25">
    <visual>
      <geometry>
        <cylinder length="0.02" radius="0.01"/>
      </geometry>
      <origin rpy="0 0 0" xyz="0 0 0.01"/>
      <material name="yellow"/>
    </visual>
    <collision>
      <geometry>
        <cylinder length="0.02" radius="0.01"/>
      </geometry>
      <origin rpy="0 0 0" xyz="0 0 0.01"/>
    </collision>
  </link>
  <joint name="balljoint_25_0" type="revolute">
    <parent link="link_24"/>
    <child link="zero_link_25_0"/>
    <origin rpy="0 0 0" xyz="0 0 0.02"/>
    <axis xyz="1 0 0"/>
    <limit effort="1000.0" lower="-0.78" upper="0.78" velocity="0.5"/>
  </joint>
  <link name="zero_link_25_0">
    <visual>
      <geometry>
        <cylinder length="0" radius="0"/>
      </geometry>
      <origin rpy="0 0 0" xyz="0 0 0"/>
    </visual>
  </link>
  <joint name="balljoint_25_1" type="revolute">
    <parent link="zero_link_25_0"/>
    <child link="zero_link_25_1"/>
    <origin rpy="0 0 0" xyz="0 0 0"/>
    <axis xyz="0 1 0"/>
    <limit effort="1000.0" lower="-0.78" upper="0.78" velocity="0.5"/>
  </joint>
  <link name="zero_link_25_1">
    <visual>
      <geometry>
        <cylinder length="0" radius="0"/>
      </geometry>
      <origin rpy="0 0 0" xyz="0 0 0"/>
    </visual>
  </link>
  <joint name="balljoint_25_2" type="revolute">
    <parent link="zero_link_25_1"/>
    <child link="link_25"/>
    <origin rpy="0 0 0" xyz="0 0 0"/>
    <axis xyz="0 0 1"/>
    <limit effort="1000.0" lower="-0.78" upper="0.78" velocity="0.5"/>
  </joint>
  <link name="link_24">
    <visual>
      <geometry>
        <cylinder length="0.02" radius="0.01"/>
      </geometry>
      <origin rpy="0 0 0" xyz="0 0 0.01"/>
      <material name="yellow"/>
    </visual>
    <collision>
      <geometry>
        <cylinder length="0.02" radius="0.01"/>
      </geometry>
      <origin rpy="0 0 0" xyz="0 0 0.01"/>
    </collision>
  </link>
  <joint name="balljoint_24_0" type="revolute">
    <parent link="link_23"/>
    <child link="zero_link_24_0"/>
    <origin rpy="0 0 0" xyz="0 0 0.02"/>
    <axis xyz="1 0 0"/>
    <limit effort="1000.0" lower="-0.78" upper="0.78" velocity="0.5"/>
  </joint>
  <link name="zero_link_24_0">
    <visual>
      <geometry>
        <cylinder length="0" radius="0"/>
      </geometry>
      <origin rpy="0 0 0" xyz="0 0 0"/>
    </visual>
  </link>
  <joint name="balljoint_24_1" type="revolute">
    <parent link="zero_link_24_0"/>
    <child link="zero_link_24_1"/>
    <origin rpy="0 0 0" xyz="0 0 0"/>
    <axis xyz="0 1 0"/>
    <limit effort="1000.0" lower="-0.78" upper="0.78" velocity="0.5"/>
  </joint>
  <link name="zero_link_24_1">
    <visual>
      <geometry>
        <cylinder length="0" radius="0"/>
      </geometry>
      <origin rpy="0 0 0" xyz="0 0 0"/>
    </visual>
  </link>
  <joint name="balljoint_24_2" type="revolute">
    <parent link="zero_link_24_1"/>
    <child link="link_24"/>
    <origin rpy="0 0 0" xyz="0 0 0"/>
    <axis xyz="0 0 1"/>
    <limit effort="1000.0" lower="-0.78" upper="0.78" velocity="0.5"/>
  </joint>
  <link name="link_23">
    <visual>
      <geometry>
        <cylinder length="0.02" radius="0.01"/>
      </geometry>
      <origin rpy="0 0 0" xyz="0 0 0.01"/>
      <material name="yellow"/>
    </visual>
    <collision>
      <geometry>
        <cylinder length="0.02" radius="0.01"/>
      </geometry>
      <origin rpy="0 0 0" xyz="0 0 0.01"/>
    </collision>
  </link>
  <joint name="balljoint_23_0" type="revolute">
    <parent link="link_22"/>
    <child link="zero_link_23_0"/>
    <origin rpy="0 0 0" xyz="0 0 0.02"/>
    <axis xyz="1 0 0"/>
    <limit effort="1000.0" lower="-0.78" upper="0.78" velocity="0.5"/>
  </joint>
  <link name="zero_link_23_0">
    <visual>
      <geometry>
        <cylinder length="0" radius="0"/>
      </geometry>
      <origin rpy="0 0 0" xyz="0 0 0"/>
    </visual>
  </link>
  <joint name="balljoint_23_1" type="revolute">
    <parent link="zero_link_23_0"/>
    <child link="zero_link_23_1"/>
    <origin rpy="0 0 0" xyz="0 0 0"/>
    <axis xyz="0 1 0"/>
    <limit effort="1000.0" lower="-0.78" upper="0.78" velocity="0.5"/>
  </joint>
  <link name="zero_link_23_1">
    <visual>
      <geometry>
        <cylinder length="0" radius="0"/>
      </geometry>
      <origin rpy="0 0 0" xyz="0 0 0"/>
    </visual>
  </link>
  <joint name="balljoint_23_2" type="revolute">
    <parent link="zero_link_23_1"/>
    <child link="link_23"/>
    <origin rpy="0 0 0" xyz="0 0 0"/>
    <axis xyz="0 0 1"/>
    <limit effort="1000.0" lower="-0.78" upper="0.78" velocity="0.5"/>
  </joint>
  <link name="link_22">
    <visual>
      <geometry>
        <cylinder length="0.02" radius="0.01"/>
      </geometry>
      <origin rpy="0 0 0" xyz="0 0 0.01"/>
      <material name="yellow"/>
    </visual>
    <collision>
      <geometry>
        <cylinder length="0.02" radius="0.01"/>
      </geometry>
      <origin rpy="0 0 0" xyz="0 0 0.01"/>
    </collision>
  </link>
  <joint name="balljoint_22_0" type="revolute">
    <parent link="link_21"/>
    <child link="zero_link_22_0"/>
    <origin rpy="0 0 0" xyz="0 0 0.02"/>
    <axis xyz="1 0 0"/>
    <limit effort="1000.0" lower="-0.78" upper="0.78" velocity="0.5"/>
  </joint>
  <link name="zero_link_22_0">
    <visual>
      <geometry>
        <cylinder length="0" radius="0"/>
      </geometry>
      <origin rpy="0 0 0" xyz="0 0 0"/>
    </visual>
  </link>
  <joint name="balljoint_22_1" type="revolute">
    <parent link="zero_link_22_0"/>
    <child link="zero_link_22_1"/>
    <origin rpy="0 0 0" xyz="0 0 0"/>
    <axis xyz="0 1 0"/>
    <limit effort="1000.0" lower="-0.78" upper="0.78" velocity="0.5"/>
  </joint>
  <link name="zero_link_22_1">
    <visual>
      <geometry>
        <cylinder length="0" radius="0"/>
      </geometry>
      <origin rpy="0 0 0" xyz="0 0 0"/>
    </visual>
  </link>
  <joint name="balljoint_22_2" type="revolute">
    <parent link="zero_link_22_1"/>
    <child link="link_22"/>
    <origin rpy="0 0 0" xyz="0 0 0"/>
    <axis xyz="0 0 1"/>
    <limit effort="1000.0" lower="-0.78" upper="0.78" velocity="0.5"/>
  </joint>
  <link name="link_21">
    <visual>
      <geometry>
        <cylinder length="0.02" radius="0.01"/>
      </geometry>
      <origin rpy="0 0 0" xyz="0 0 0.01"/>
      <material name="yellow"/>
    </visual>
    <collision>
      <geometry>
        <cylinder length="0.02" radius="0.01"/>
      </geometry>
      <origin rpy="0 0 0" xyz="0 0 0.01"/>
    </collision>
  </link>
  <joint name="balljoint_21_0" type="revolute">
    <parent link="link_20"/>
    <child link="zero_link_21_0"/>
    <origin rpy="0 0 0" xyz="0 0 0.02"/>
    <axis xyz="1 0 0"/>
    <limit effort="1000.0" lower="-0.78" upper="0.78" velocity="0.5"/>
  </joint>
  <link name="zero_link_21_0">
    <visual>
      <geometry>
        <cylinder length="0" radius="0"/>
      </geometry>
      <origin rpy="0 0 0" xyz="0 0 0"/>
    </visual>
  </link>
  <joint name="balljoint_21_1" type="revolute">
    <parent link="zero_link_21_0"/>
    <child link="zero_link_21_1"/>
    <origin rpy="0 0 0" xyz="0 0 0"/>
    <axis xyz="0 1 0"/>
    <limit effort="1000.0" lower="-0.78" upper="0.78" velocity="0.5"/>
  </joint>
  <link name="zero_link_21_1">
    <visual>
      <geometry>
        <cylinder length="0" radius="0"/>
      </geometry>
      <origin rpy="0 0 0" xyz="0 0 0"/>
    </visual>
  </link>
  <joint name="balljoint_21_2" type="revolute">
    <parent link="zero_link_21_1"/>
    <child link="link_21"/>
    <origin rpy="0 0 0" xyz="0 0 0"/>
    <axis xyz="0 0 1"/>
    <limit effort="1000.0" lower="-0.78" upper="0.78" velocity="0.5"/>
  </joint>
  <link name="link_20">
    <visual>
      <geometry>
        <cylinder length="0.02" radius="0.01"/>
      </geometry>
      <origin rpy="0 0 0" xyz="0 0 0.01"/>
      <material name="yellow"/>
    </visual>
    <collision>
      <geometry>
        <cylinder length="0.02" radius="0.01"/>
      </geometry>
      <origin rpy="0 0 0" xyz="0 0 0.01"/>
    </collision>
  </link>
  <joint name="balljoint_20_0" type="revolute">
    <parent link="link_19"/>
    <child link="zero_link_20_0"/>
    <origin rpy="0 0 0" xyz="0 0 0.02"/>
    <axis xyz="1 0 0"/>
    <limit effort="1000.0" lower="-0.78" upper="0.78" velocity="0.5"/>
  </joint>
  <link name="zero_link_20_0">
    <visual>
      <geometry>
        <cylinder length="0" radius="0"/>
      </geometry>
      <origin rpy="0 0 0" xyz="0 0 0"/>
    </visual>
  </link>
  <joint name="balljoint_20_1" type="revolute">
    <parent link="zero_link_20_0"/>
    <child link="zero_link_20_1"/>
    <origin rpy="0 0 0" xyz="0 0 0"/>
    <axis xyz="0 1 0"/>
    <limit effort="1000.0" lower="-0.78" upper="0.78" velocity="0.5"/>
  </joint>
  <link name="zero_link_20_1">
    <visual>
      <geometry>
        <cylinder length="0" radius="0"/>
      </geometry>
      <origin rpy="0 0 0" xyz="0 0 0"/>
    </visual>
  </link>
  <joint name="balljoint_20_2" type="revolute">
    <parent link="zero_link_20_1"/>
    <child link="link_20"/>
    <origin rpy="0 0 0" xyz="0 0 0"/>
    <axis xyz="0 0 1"/>
    <limit effort="1000.0" lower="-0.78" upper="0.78" velocity="0.5"/>
  </joint>
  <link name="link_19">
    <visual>
      <geometry>
        <cylinder length="0.02" radius="0.01"/>
      </geometry>
      <origin rpy="0 0 0" xyz="0 0 0.01"/>
      <material name="yellow"/>
    </visual>
    <collision>
      <geometry>
        <cylinder length="0.02" radius="0.01"/>
      </geometry>
      <origin rpy="0 0 0" xyz="0 0 0.01"/>
    </collision>
  </link>
  <joint name="balljoint_19_0" type="revolute">
    <parent link="link_18"/>
    <child link="zero_link_19_0"/>
    <origin rpy="0 0 0" xyz="0 0 0.02"/>
    <axis xyz="1 0 0"/>
    <limit effort="1000.0" lower="-0.78" upper="0.78" velocity="0.5"/>
  </joint>
  <link name="zero_link_19_0">
    <visual>
      <geometry>
        <cylinder length="0" radius="0"/>
      </geometry>
      <origin rpy="0 0 0" xyz="0 0 0"/>
    </visual>
  </link>
  <joint name="balljoint_19_1" type="revolute">
    <parent link="zero_link_19_0"/>
    <child link="zero_link_19_1"/>
    <origin rpy="0 0 0" xyz="0 0 0"/>
    <axis xyz="0 1 0"/>
    <limit effort="1000.0" lower="-0.78" upper="0.78" velocity="0.5"/>
  </joint>
  <link name="zero_link_19_1">
    <visual>
      <geometry>
        <cylinder length="0" radius="0"/>
      </geometry>
      <origin rpy="0 0 0" xyz="0 0 0"/>
    </visual>
  </link>
  <joint name="balljoint_19_2" type="revolute">
    <parent link="zero_link_19_1"/>
    <child link="link_19"/>
    <origin rpy="0 0 0" xyz="0 0 0"/>
    <axis xyz="0 0 1"/>
    <limit effort="1000.0" lower="-0.78" upper="0.78" velocity="0.5"/>
  </joint>
  <link name="link_18">
    <visual>
      <geometry>
        <cylinder length="0.02" radius="0.01"/>
      </geometry>
      <origin rpy="0 0 0" xyz="0 0 0.01"/>
      <material name="yellow"/>
    </visual>
    <collision>
      <geometry>
        <cylinder length="0.02" radius="0.01"/>
      </geometry>
      <origin rpy="0 0 0" xyz="0 0 0.01"/>
    </collision>
  </link>
  <joint name="balljoint_18_0" type="revolute">
    <parent link="link_17"/>
    <child link="zero_link_18_0"/>
    <origin rpy="0 0 0" xyz="0 0 0.02"/>
    <axis xyz="1 0 0"/>
    <limit effort="1000.0" lower="-0.78" upper="0.78" velocity="0.5"/>
  </joint>
  <link name="zero_link_18_0">
    <visual>
      <geometry>
        <cylinder length="0" radius="0"/>
      </geometry>
      <origin rpy="0 0 0" xyz="0 0 0"/>
    </visual>
  </link>
  <joint name="balljoint_18_1" type="revolute">
    <parent link="zero_link_18_0"/>
    <child link="zero_link_18_1"/>
    <origin rpy="0 0 0" xyz="0 0 0"/>
    <axis xyz="0 1 0"/>
    <limit effort="1000.0" lower="-0.78" upper="0.78" velocity="0.5"/>
  </joint>
  <link name="zero_link_18_1">
    <visual>
      <geometry>
        <cylinder length="0" radius="0"/>
      </geometry>
      <origin rpy="0 0 0" xyz="0 0 0"/>
    </visual>
  </link>
  <joint name="balljoint_18_2" type="revolute">
    <parent link="zero_link_18_1"/>
    <child link="link_18"/>
    <origin rpy="0 0 0" xyz="0 0 0"/>
    <axis xyz="0 0 1"/>
    <limit effort="1000.0" lower="-0.78" upper="0.78" velocity="0.5"/>
  </joint>
  <link name="link_17">
    <visual>
      <geometry>
        <cylinder length="0.02" radius="0.01"/>
      </geometry>
      <origin rpy="0 0 0" xyz="0 0 0.01"/>
      <material name="yellow"/>
    </visual>
    <collision>
      <geometry>
        <cylinder length="0.02" radius="0.01"/>
      </geometry>
      <origin rpy="0 0 0" xyz="0 0 0.01"/>
    </collision>
  </link>
  <joint name="balljoint_17_0" type="revolute">
    <parent link="link_16"/>
    <child link="zero_link_17_0"/>
    <origin rpy="0 0 0" xyz="0 0 0.02"/>
    <axis xyz="1 0 0"/>
    <limit effort="1000.0" lower="-0.78" upper="0.78" velocity="0.5"/>
  </joint>
  <link name="zero_link_17_0">
    <visual>
      <geometry>
        <cylinder length="0" radius="0"/>
      </geometry>
      <origin rpy="0 0 0" xyz="0 0 0"/>
    </visual>
  </link>
  <joint name="balljoint_17_1" type="revolute">
    <parent link="zero_link_17_0"/>
    <child link="zero_link_17_1"/>
    <origin rpy="0 0 0" xyz="0 0 0"/>
    <axis xyz="0 1 0"/>
    <limit effort="1000.0" lower="-0.78" upper="0.78" velocity="0.5"/>
  </joint>
  <link name="zero_link_17_1">
    <visual>
      <geometry>
        <cylinder length="0" radius="0"/>
      </geometry>
      <origin rpy="0 0 0" xyz="0 0 0"/>
    </visual>
  </link>
  <joint name="balljoint_17_2" type="revolute">
    <parent link="zero_link_17_1"/>
    <child link="link_17"/>
    <origin rpy="0 0 0" xyz="0 0 0"/>
    <axis xyz="0 0 1"/>
    <limit effort="1000.0" lower="-0.78" upper="0.78" velocity="0.5"/>
  </joint>
  <link name="link_16">
    <visual>
      <geometry>
        <cylinder length="0.02" radius="0.01"/>
      </geometry>
      <origin rpy="0 0 0" xyz="0 0 0.01"/>
      <material name="yellow"/>
    </visual>
    <collision>
      <geometry>
        <cylinder length="0.02" radius="0.01"/>
      </geometry>
      <origin rpy="0 0 0" xyz="0 0 0.01"/>
    </collision>
  </link>
  <joint name="balljoint_16_0" type="revolute">
    <parent link="link_15"/>
    <child link="zero_link_16_0"/>
    <origin rpy="0 0 0" xyz="0 0 0.02"/>
    <axis xyz="1 0 0"/>
    <limit effort="1000.0" lower="-0.78" upper="0.78" velocity="0.5"/>
  </joint>
  <link name="zero_link_16_0">
    <visual>
      <geometry>
        <cylinder length="0" radius="0"/>
      </geometry>
      <origin rpy="0 0 0" xyz="0 0 0"/>
    </visual>
  </link>
  <joint name="balljoint_16_1" type="revolute">
    <parent link="zero_link_16_0"/>
    <child link="zero_link_16_1"/>
    <origin rpy="0 0 0" xyz="0 0 0"/>
    <axis xyz="0 1 0"/>
    <limit effort="1000.0" lower="-0.78" upper="0.78" velocity="0.5"/>
  </joint>
  <link name="zero_link_16_1">
    <visual>
      <geometry>
        <cylinder length="0" radius="0"/>
      </geometry>
      <origin rpy="0 0 0" xyz="0 0 0"/>
    </visual>
  </link>
  <joint name="balljoint_16_2" type="revolute">
    <parent link="zero_link_16_1"/>
    <child link="link_16"/>
    <origin rpy="0 0 0" xyz="0 0 0"/>
    <axis xyz="0 0 1"/>
    <limit effort="1000.0" lower="-0.78" upper="0.78" velocity="0.5"/>
  </joint>
  <link name="link_15">
    <visual>
      <geometry>
        <cylinder length="0.02" radius="0.01"/>
      </geometry>
      <origin rpy="0 0 0" xyz="0 0 0.01"/>
      <material name="yellow"/>
    </visual>
    <collision>
      <geometry>
        <cylinder length="0.02" radius="0.01"/>
      </geometry>
      <origin rpy="0 0 0" xyz="0 0 0.01"/>
    </collision>
  </link>
  <joint name="balljoint_15_0" type="revolute">
    <parent link="link_14"/>
    <child link="zero_link_15_0"/>
    <origin rpy="0 0 0" xyz="0 0 0.02"/>
    <axis xyz="1 0 0"/>
    <limit effort="1000.0" lower="-0.78" upper="0.78" velocity="0.5"/>
  </joint>
  <link name="zero_link_15_0">
    <visual>
      <geometry>
        <cylinder length="0" radius="0"/>
      </geometry>
      <origin rpy="0 0 0" xyz="0 0 0"/>
    </visual>
  </link>
  <joint name="balljoint_15_1" type="revolute">
    <parent link="zero_link_15_0"/>
    <child link="zero_link_15_1"/>
    <origin rpy="0 0 0" xyz="0 0 0"/>
    <axis xyz="0 1 0"/>
    <limit effort="1000.0" lower="-0.78" upper="0.78" velocity="0.5"/>
  </joint>
  <link name="zero_link_15_1">
    <visual>
      <geometry>
        <cylinder length="0" radius="0"/>
      </geometry>
      <origin rpy="0 0 0" xyz="0 0 0"/>
    </visual>
  </link>
  <joint name="balljoint_15_2" type="revolute">
    <parent link="zero_link_15_1"/>
    <child link="link_15"/>
    <origin rpy="0 0 0" xyz="0 0 0"/>
    <axis xyz="0 0 1"/>
    <limit effort="1000.0" lower="-0.78" upper="0.78" velocity="0.5"/>
  </joint>
  <link name="link_14">
    <visual>
      <geometry>
        <cylinder length="0.02" radius="0.01"/>
      </geometry>
      <origin rpy="0 0 0" xyz="0 0 0.01"/>
      <material name="yellow"/>
    </visual>
    <collision>
      <geometry>
        <cylinder length="0.02" radius="0.01"/>
      </geometry>
      <origin rpy="0 0 0" xyz="0 0 0.01"/>
    </collision>
  </link>
  <joint name="balljoint_14_0" type="revolute">
    <parent link="link_13"/>
    <child link="zero_link_14_0"/>
    <origin rpy="0 0 0" xyz="0 0 0.02"/>
    <axis xyz="1 0 0"/>
    <limit effort="1000.0" lower="-0.78" upper="0.78" velocity="0.5"/>
  </joint>
  <link name="zero_link_14_0">
    <visual>
      <geometry>
        <cylinder length="0" radius="0"/>
      </geometry>
      <origin rpy="0 0 0" xyz="0 0 0"/>
    </visual>
  </link>
  <joint name="balljoint_14_1" type="revolute">
    <parent link="zero_link_14_0"/>
    <child link="zero_link_14_1"/>
    <origin rpy="0 0 0" xyz="0 0 0"/>
    <axis xyz="0 1 0"/>
    <limit effort="1000.0" lower="-0.78" upper="0.78" velocity="0.5"/>
  </joint>
  <link name="zero_link_14_1">
    <visual>
      <geometry>
        <cylinder length="0" radius="0"/>
      </geometry>
      <origin rpy="0 0 0" xyz="0 0 0"/>
    </visual>
  </link>
  <joint name="balljoint_14_2" type="revolute">
    <parent link="zero_link_14_1"/>
    <child link="link_14"/>
    <origin rpy="0 0 0" xyz="0 0 0"/>
    <axis xyz="0 0 1"/>
    <limit effort="1000.0" lower="-0.78" upper="0.78" velocity="0.5"/>
  </joint>
  <link name="link_13">
    <visual>
      <geometry>
        <cylinder length="0.02" radius="0.01"/>
      </geometry>
      <origin rpy="0 0 0" xyz="0 0 0.01"/>
      <material name="yellow"/>
    </visual>
    <collision>
      <geometry>
        <cylinder length="0.02" radius="0.01"/>
      </geometry>
      <origin rpy="0 0 0" xyz="0 0 0.01"/>
    </collision>
  </link>
  <joint name="balljoint_13_0" type="revolute">
    <parent link="link_12"/>
    <child link="zero_link_13_0"/>
    <origin rpy="0 0 0" xyz="0 0 0.02"/>
    <axis xyz="1 0 0"/>
    <limit effort="1000.0" lower="-0.78" upper="0.78" velocity="0.5"/>
  </joint>
  <link name="zero_link_13_0">
    <visual>
      <geometry>
        <cylinder length="0" radius="0"/>
      </geometry>
      <origin rpy="0 0 0" xyz="0 0 0"/>
    </visual>
  </link>
  <joint name="balljoint_13_1" type="revolute">
    <parent link="zero_link_13_0"/>
    <child link="zero_link_13_1"/>
    <origin rpy="0 0 0" xyz="0 0 0"/>
    <axis xyz="0 1 0"/>
    <limit effort="1000.0" lower="-0.78" upper="0.78" velocity="0.5"/>
  </joint>
  <link name="zero_link_13_1">
    <visual>
      <geometry>
        <cylinder length="0" radius="0"/>
      </geometry>
      <origin rpy="0 0 0" xyz="0 0 0"/>
    </visual>
  </link>
  <joint name="balljoint_13_2" type="revolute">
    <parent link="zero_link_13_1"/>
    <child link="link_13"/>
    <origin rpy="0 0 0" xyz="0 0 0"/>
    <axis xyz="0 0 1"/>
    <limit effort="1000.0" lower="-0.78" upper="0.78" velocity="0.5"/>
  </joint>
  <link name="link_12">
    <visual>
      <geometry>
        <cylinder length="0.02" radius="0.01"/>
      </geometry>
      <origin rpy="0 0 0" xyz="0 0 0.01"/>
      <material name="yellow"/>
    </visual>
    <collision>
      <geometry>
        <cylinder length="0.02" radius="0.01"/>
      </geometry>
      <origin rpy="0 0 0" xyz="0 0 0.01"/>
    </collision>
  </link>
  <joint name="balljoint_12_0" type="revolute">
    <parent link="link_11"/>
    <child link="zero_link_12_0"/>
    <origin rpy="0 0 0" xyz="0 0 0.02"/>
    <axis xyz="1 0 0"/>
    <limit effort="1000.0" lower="-0.78" upper="0.78" velocity="0.5"/>
  </joint>
  <link name="zero_link_12_0">
    <visual>
      <geometry>
        <cylinder length="0" radius="0"/>
      </geometry>
      <origin rpy="0 0 0" xyz="0 0 0"/>
    </visual>
  </link>
  <joint name="balljoint_12_1" type="revolute">
    <parent link="zero_link_12_0"/>
    <child link="zero_link_12_1"/>
    <origin rpy="0 0 0" xyz="0 0 0"/>
    <axis xyz="0 1 0"/>
    <limit effort="1000.0" lower="-0.78" upper="0.78" velocity="0.5"/>
  </joint>
  <link name="zero_link_12_1">
    <visual>
      <geometry>
        <cylinder length="0" radius="0"/>
      </geometry>
      <origin rpy="0 0 0" xyz="0 0 0"/>
    </visual>
  </link>
  <joint name="balljoint_12_2" type="revolute">
    <parent link="zero_link_12_1"/>
    <child link="link_12"/>
    <origin rpy="0 0 0" xyz="0 0 0"/>
    <axis xyz="0 0 1"/>
    <limit effort="1000.0" lower="-0.78" upper="0.78" velocity="0.5"/>
  </joint>
  <link name="link_11">
    <visual>
      <geometry>
        <cylinder length="0.02" radius="0.01"/>
      </geometry>
      <origin rpy="0 0 0" xyz="0 0 0.01"/>
      <material name="yellow"/>
    </visual>
    <collision>
      <geometry>
        <cylinder length="0.02" radius="0.01"/>
      </geometry>
      <origin rpy="0 0 0" xyz="0 0 0.01"/>
    </collision>
  </link>
  <joint name="balljoint_11_0" type="revolute">
    <parent link="link_10"/>
    <child link="zero_link_11_0"/>
    <origin rpy="0 0 0" xyz="0 0 0.02"/>
    <axis xyz="1 0 0"/>
    <limit effort="1000.0" lower="-0.78" upper="0.78" velocity="0.5"/>
  </joint>
  <link name="zero_link_11_0">
    <visual>
      <geometry>
        <cylinder length="0" radius="0"/>
      </geometry>
      <origin rpy="0 0 0" xyz="0 0 0"/>
    </visual>
  </link>
  <joint name="balljoint_11_1" type="revolute">
    <parent link="zero_link_11_0"/>
    <child link="zero_link_11_1"/>
    <origin rpy="0 0 0" xyz="0 0 0"/>
    <axis xyz="0 1 0"/>
    <limit effort="1000.0" lower="-0.78" upper="0.78" velocity="0.5"/>
  </joint>
  <link name="zero_link_11_1">
    <visual>
      <geometry>
        <cylinder length="0" radius="0"/>
      </geometry>
      <origin rpy="0 0 0" xyz="0 0 0"/>
    </visual>
  </link>
  <joint name="balljoint_11_2" type="revolute">
    <parent link="zero_link_11_1"/>
    <child link="link_11"/>
    <origin rpy="0 0 0" xyz="0 0 0"/>
    <axis xyz="0 0 1"/>
    <limit effort="1000.0" lower="-0.78" upper="0.78" velocity="0.5"/>
  </joint>
  <link name="link_10">
    <visual>
      <geometry>
        <cylinder length="0.02" radius="0.01"/>
      </geometry>
      <origin rpy="0 0 0" xyz="0 0 0.01"/>
      <material name="yellow"/>
    </visual>
    <collision>
      <geometry>
        <cylinder length="0.02" radius="0.01"/>
      </geometry>
      <origin rpy="0 0 0" xyz="0 0 0.01"/>
    </collision>
  </link>
  <joint name="balljoint_10_0" type="revolute">
    <parent link="link_9"/>
    <child link="zero_link_10_0"/>
    <origin rpy="0 0 0" xyz="0 0 0.02"/>
    <axis xyz="1 0 0"/>
    <limit effort="1000.0" lower="-0.78" upper="0.78" velocity="0.5"/>
  </joint>
  <link name="zero_link_10_0">
    <visual>
      <geometry>
        <cylinder length="0" radius="0"/>
      </geometry>
      <origin rpy="0 0 0" xyz="0 0 0"/>
    </visual>
  </link>
  <joint name="balljoint_10_1" type="revolute">
    <parent link="zero_link_10_0"/>
    <child link="zero_link_10_1"/>
    <origin rpy="0 0 0" xyz="0 0 0"/>
    <axis xyz="0 1 0"/>
    <limit effort="1000.0" lower="-0.78" upper="0.78" velocity="0.5"/>
  </joint>
  <link name="zero_link_10_1">
    <visual>
      <geometry>
        <cylinder length="0" radius="0"/>
      </geometry>
      <origin rpy="0 0 0" xyz="0 0 0"/>
    </visual>
  </link>
  <joint name="balljoint_10_2" type="revolute">
    <parent link="zero_link_10_1"/>
    <child link="link_10"/>
    <origin rpy="0 0 0" xyz="0 0 0"/>
    <axis xyz="0 0 1"/>
    <limit effort="1000.0" lower="-0.78" upper="0.78" velocity="0.5"/>
  </joint>
  <link name="link_9">
    <visual>
      <geometry>
        <cylinder length="0.02" radius="0.01"/>
      </geometry>
      <origin rpy="0 0 0" xyz="0 0 0.01"/>
      <material name="yellow"/>
    </visual>
    <collision>
      <geometry>
        <cylinder length="0.02" radius="0.01"/>
      </geometry>
      <origin rpy="0 0 0" xyz="0 0 0.01"/>
    </collision>
  </link>
  <joint name="balljoint_9_0" type="revolute">
    <parent link="link_8"/>
    <child link="zero_link_9_0"/>
    <origin rpy="0 0 0" xyz="0 0 0.02"/>
    <axis xyz="1 0 0"/>
    <limit effort="1000.0" lower="-0.78" upper="0.78" velocity="0.5"/>
  </joint>
  <link name="zero_link_9_0">
    <visual>
      <geometry>
        <cylinder length="0" radius="0"/>
      </geometry>
      <origin rpy="0 0 0" xyz="0 0 0"/>
    </visual>
  </link>
  <joint name="balljoint_9_1" type="revolute">
    <parent link="zero_link_9_0"/>
    <child link="zero_link_9_1"/>
    <origin rpy="0 0 0" xyz="0 0 0"/>
    <axis xyz="0 1 0"/>
    <limit effort="1000.0" lower="-0.78" upper="0.78" velocity="0.5"/>
  </joint>
  <link name="zero_link_9_1">
    <visual>
      <geometry>
        <cylinder length="0" radius="0"/>
      </geometry>
      <origin rpy="0 0 0" xyz="0 0 0"/>
    </visual>
  </link>
  <joint name="balljoint_9_2" type="revolute">
    <parent link="zero_link_9_1"/>
    <child link="link_9"/>
    <origin rpy="0 0 0" xyz="0 0 0"/>
    <axis xyz="0 0 1"/>
    <limit effort="1000.0" lower="-0.78" upper="0.78" velocity="0.5"/>
  </joint>
  <link name="link_8">
    <visual>
      <geometry>
        <cylinder length="0.02" radius="0.01"/>
      </geometry>
      <origin rpy="0 0 0" xyz="0 0 0.01"/>
      <material name="yellow"/>
    </visual>
    <collision>
      <geometry>
        <cylinder length="0.02" radius="0.01"/>
      </geometry>
      <origin rpy="0 0 0" xyz="0 0 0.01"/>
    </collision>
  </link>
  <joint name="balljoint_8_0" type="revolute">
    <parent link="link_7"/>
    <child link="zero_link_8_0"/>
    <origin rpy="0 0 0" xyz="0 0 0.02"/>
    <axis xyz="1 0 0"/>
    <limit effort="1000.0" lower="-0.78" upper="0.78" velocity="0.5"/>
  </joint>
  <link name="zero_link_8_0">
    <visual>
      <geometry>
        <cylinder length="0" radius="0"/>
      </geometry>
      <origin rpy="0 0 0" xyz="0 0 0"/>
    </visual>
  </link>
  <joint name="balljoint_8_1" type="revolute">
    <parent link="zero_link_8_0"/>
    <child link="zero_link_8_1"/>
    <origin rpy="0 0 0" xyz="0 0 0"/>
    <axis xyz="0 1 0"/>
    <limit effort="1000.0" lower="-0.78" upper="0.78" velocity="0.5"/>
  </joint>
  <link name="zero_link_8_1">
    <visual>
      <geometry>
        <cylinder length="0" radius="0"/>
      </geometry>
      <origin rpy="0 0 0" xyz="0 0 0"/>
    </visual>
  </link>
  <joint name="balljoint_8_2" type="revolute">
    <parent link="zero_link_8_1"/>
    <child link="link_8"/>
    <origin rpy="0 0 0" xyz="0 0 0"/>
    <axis xyz="0 0 1"/>
    <limit effort="1000.0" lower="-0.78" upper="0.78" velocity="0.5"/>
  </joint>
  <link name="link_7">
    <visual>
      <geometry>
        <cylinder length="0.02" radius="0.01"/>
      </geometry>
      <origin rpy="0 0 0" xyz="0 0 0.01"/>
      <material name="yellow"/>
    </visual>
    <collision>
      <geometry>
        <cylinder length="0.02" radius="0.01"/>
      </geometry>
      <origin rpy="0 0 0" xyz="0 0 0.01"/>
    </collision>
  </link>
  <joint name="balljoint_7_0" type="revolute">
    <parent link="link_6"/>
    <child link="zero_link_7_0"/>
    <origin rpy="0 0 0" xyz="0 0 0.02"/>
    <axis xyz="1 0 0"/>
    <limit effort="1000.0" lower="-0.78" upper="0.78" velocity="0.5"/>
  </joint>
  <link name="zero_link_7_0">
    <visual>
      <geometry>
        <cylinder length="0" radius="0"/>
      </geometry>
      <origin rpy="0 0 0" xyz="0 0 0"/>
    </visual>
  </link>
  <joint name="balljoint_7_1" type="revolute">
    <parent link="zero_link_7_0"/>
    <child link="zero_link_7_1"/>
    <origin rpy="0 0 0" xyz="0 0 0"/>
    <axis xyz="0 1 0"/>
    <limit effort="1000.0" lower="-0.78" upper="0.78" velocity="0.5"/>
  </joint>
  <link name="zero_link_7_1">
    <visual>
      <geometry>
        <cylinder length="0" radius="0"/>
      </geometry>
      <origin rpy="0 0 0" xyz="0 0 0"/>
    </visual>
  </link>
  <joint name="balljoint_7_2" type="revolute">
    <parent link="zero_link_7_1"/>
    <child link="link_7"/>
    <origin rpy="0 0 0" xyz="0 0 0"/>
    <axis xyz="0 0 1"/>
    <limit effort="1000.0" lower="-0.78" upper="0.78" velocity="0.5"/>
  </joint>
  <link name="link_6">
    <visual>
      <geometry>
        <cylinder length="0.02" radius="0.01"/>
      </geometry>
      <origin rpy="0 0 0" xyz="0 0 0.01"/>
      <material name="yellow"/>
    </visual>
    <collision>
      <geometry>
        <cylinder length="0.02" radius="0.01"/>
      </geometry>
      <origin rpy="0 0 0" xyz="0 0 0.01"/>
    </collision>
  </link>
  <joint name="balljoint_6_0" type="revolute">
    <parent link="link_5"/>
    <child link="zero_link_6_0"/>
    <origin rpy="0 0 0" xyz="0 0 0.02"/>
    <axis xyz="1 0 0"/>
    <limit effort="1000.0" lower="-0.78" upper="0.78" velocity="0.5"/>
  </joint>
  <link name="zero_link_6_0">
    <visual>
      <geometry>
        <cylinder length="0" radius="0"/>
      </geometry>
      <origin rpy="0 0 0" xyz="0 0 0"/>
    </visual>
  </link>
  <joint name="balljoint_6_1" type="revolute">
    <parent link="zero_link_6_0"/>
    <child link="zero_link_6_1"/>
    <origin rpy="0 0 0" xyz="0 0 0"/>
    <axis xyz="0 1 0"/>
    <limit effort="1000.0" lower="-0.78" upper="0.78" velocity="0.5"/>
  </joint>
  <link name="zero_link_6_1">
    <visual>
      <geometry>
        <cylinder length="0" radius="0"/>
      </geometry>
      <origin rpy="0 0 0" xyz="0 0 0"/>
    </visual>
  </link>
  <joint name="balljoint_6_2" type="revolute">
    <parent link="zero_link_6_1"/>
    <child link="link_6"/>
    <origin rpy="0 0 0" xyz="0 0 0"/>
    <axis xyz="0 0 1"/>
    <limit effort="1000.0" lower="-0.78" upper="0.78" velocity="0.5"/>
  </joint>
  <link name="link_5">
    <visual>
      <geometry>
        <cylinder length="0.02" radius="0.01"/>
      </geometry>
      <origin rpy="0 0 0" xyz="0 0 0.01"/>
      <material name="yellow"/>
    </visual>
    <collision>
      <geometry>
        <cylinder length="0.02" radius="0.01"/>
      </geometry>
      <origin rpy="0 0 0" xyz="0 0 0.01"/>
    </collision>
  </link>
  <joint name="balljoint_5_0" type="revolute">
    <parent link="link_4"/>
    <child link="zero_link_5_0"/>
    <origin rpy="0 0 0" xyz="0 0 0.02"/>
    <axis xyz="1 0 0"/>
    <limit effort="1000.0" lower="-0.78" upper="0.78" velocity="0.5"/>
  </joint>
  <link name="zero_link_5_0">
    <visual>
      <geometry>
        <cylinder length="0" radius="0"/>
      </geometry>
      <origin rpy="0 0 0" xyz="0 0 0"/>
    </visual>
  </link>
  <joint name="balljoint_5_1" type="revolute">
    <parent link="zero_link_5_0"/>
    <child link="zero_link_5_1"/>
    <origin rpy="0 0 0" xyz="0 0 0"/>
    <axis xyz="0 1 0"/>
    <limit effort="1000.0" lower="-0.78" upper="0.78" velocity="0.5"/>
  </joint>
  <link name="zero_link_5_1">
    <visual>
      <geometry>
        <cylinder length="0" radius="0"/>
      </geometry>
      <origin rpy="0 0 0" xyz="0 0 0"/>
    </visual>
  </link>
  <joint name="balljoint_5_2" type="revolute">
    <parent link="zero_link_5_1"/>
    <child link="link_5"/>
    <origin rpy="0 0 0" xyz="0 0 0"/>
    <axis xyz="0 0 1"/>
    <limit effort="1000.0" lower="-0.78" upper="0.78" velocity="0.5"/>
  </joint>
  <link name="link_4">
    <visual>
      <geometry>
        <cylinder length="0.02" radius="0.01"/>
      </geometry>
      <origin rpy="0 0 0" xyz="0 0 0.01"/>
      <material name="yellow"/>
    </visual>
    <collision>
      <geometry>
        <cylinder length="0.02" radius="0.01"/>
      </geometry>
      <origin rpy="0 0 0" xyz="0 0 0.01"/>
    </collision>
  </link>
  <joint name="balljoint_4_0" type="revolute">
    <parent link="link_3"/>
    <child link="zero_link_4_0"/>
    <origin rpy="0 0 0" xyz="0 0 0.02"/>
    <axis xyz="1 0 0"/>
    <limit effort="1000.0" lower="-0.78" upper="0.78" velocity="0.5"/>
  </joint>
  <link name="zero_link_4_0">
    <visual>
      <geometry>
        <cylinder length="0" radius="0"/>
      </geometry>
      <origin rpy="0 0 0" xyz="0 0 0"/>
    </visual>
  </link>
  <joint name="balljoint_4_1" type="revolute">
    <parent link="zero_link_4_0"/>
    <child link="zero_link_4_1"/>
    <origin rpy="0 0 0" xyz="0 0 0"/>
    <axis xyz="0 1 0"/>
    <limit effort="1000.0" lower="-0.78" upper="0.78" velocity="0.5"/>
  </joint>
  <link name="zero_link_4_1">
    <visual>
      <geometry>
        <cylinder length="0" radius="0"/>
      </geometry>
      <origin rpy="0 0 0" xyz="0 0 0"/>
    </visual>
  </link>
  <joint name="balljoint_4_2" type="revolute">
    <parent link="zero_link_4_1"/>
    <child link="link_4"/>
    <origin rpy="0 0 0" xyz="0 0 0"/>
    <axis xyz="0 0 1"/>
    <limit effort="1000.0" lower="-0.78" upper="0.78" velocity="0.5"/>
  </joint>
  <link name="link_3">
    <visual>
      <geometry>
        <cylinder length="0.02" radius="0.01"/>
      </geometry>
      <origin rpy="0 0 0" xyz="0 0 0.01"/>
      <material name="yellow"/>
    </visual>
    <collision>
      <geometry>
        <cylinder length="0.02" radius="0.01"/>
      </geometry>
      <origin rpy="0 0 0" xyz="0 0 0.01"/>
    </collision>
  </link>
  <joint name="balljoint_3_0" type="revolute">
    <parent link="link_2"/>
    <child link="zero_link_3_0"/>
    <origin rpy="0 0 0" xyz="0 0 0.02"/>
    <axis xyz="1 0 0"/>
    <limit effort="1000.0" lower="-0.78" upper="0.78" velocity="0.5"/>
  </joint>
  <link name="zero_link_3_0">
    <visual>
      <geometry>
        <cylinder length="0" radius="0"/>
      </geometry>
      <origin rpy="0 0 0" xyz="0 0 0"/>
    </visual>
  </link>
  <joint name="balljoint_3_1" type="revolute">
    <parent link="zero_link_3_0"/>
    <child link="zero_link_3_1"/>
    <origin rpy="0 0 0" xyz="0 0 0"/>
    <axis xyz="0 1 0"/>
    <limit effort="1000.0" lower="-0.78" upper="0.78" velocity="0.5"/>
  </joint>
  <link name="zero_link_3_1">
    <visual>
      <geometry>
        <cylinder length="0" radius="0"/>
      </geometry>
      <origin rpy="0 0 0" xyz="0 0 0"/>
    </visual>
  </link>
  <joint name="balljoint_3_2" type="revolute">
    <parent link="zero_link_3_1"/>
    <child link="link_3"/>
    <origin rpy="0 0 0" xyz="0 0 0"/>
    <axis xyz="0 0 1"/>
    <limit effort="1000.0" lower="-0.78" upper="0.78" velocity="0.5"/>
  </joint>
  <link name="link_2">
    <visual>
      <geometry>
        <cylinder length="0.02" radius="0.01"/>
      </geometry>
      <origin rpy="0 0 0" xyz="0 0 0.01"/>
      <material name="yellow"/>
    </visual>
    <collision>
      <geometry>
        <cylinder length="0.02" radius="0.01"/>
      </geometry>
      <origin rpy="0 0 0" xyz="0 0 0.01"/>
    </collision>
  </link>
  <joint name="balljoint_2_0" type="revolute">
    <parent link="link_1"/>
    <child link="zero_link_2_0"/>
    <origin rpy="0 0 0" xyz="0 0 0.02"/>
    <axis xyz="1 0 0"/>
    <limit effort="1000.0" lower="-0.78" upper="0.78" velocity="0.5"/>
  </joint>
  <link name="zero_link_2_0">
    <visual>
      <geometry>
        <cylinder length="0" radius="0"/>
      </geometry>
      <origin rpy="0 0 0" xyz="0 0 0"/>
    </visual>
  </link>
  <joint name="balljoint_2_1" type="revolute">
    <parent link="zero_link_2_0"/>
    <child link="zero_link_2_1"/>
    <origin rpy="0 0 0" xyz="0 0 0"/>
    <axis xyz="0 1 0"/>
    <limit effort="1000.0" lower="-0.78" upper="0.78" velocity="0.5"/>
  </joint>
  <link name="zero_link_2_1">
    <visual>
      <geometry>
        <cylinder length="0" radius="0"/>
      </geometry>
      <origin rpy="0 0 0" xyz="0 0 0"/>
    </visual>
  </link>
  <joint name="balljoint_2_2" type="revolute">
    <parent link="zero_link_2_1"/>
    <child link="link_2"/>
    <origin rpy="0 0 0" xyz="0 0 0"/>
    <axis xyz="0 0 1"/>
    <limit effort="1000.0" lower="-0.78" upper="0.78" velocity="0.5"/>
  </joint>
  <link name="link_1">
    <visual>
      <geometry>
        <cylinder length="0.02" radius="0.01"/>
      </geometry>
      <origin rpy="0 0 0" xyz="0 0 0.01"/>
      <material name="yellow"/>
    </visual>
    <collision>
      <geometry>
        <cylinder length="0.02" radius="0.01"/>
      </geometry>
      <origin rpy="0 0 0" xyz="0 0 0.01"/>
    </collision>
  </link>
  <joint name="balljoint_1_0" type="revolute">
    <parent link="link_0"/>
    <child link="zero_link_1_0"/>
    <origin rpy="0 0 0" xyz="0 0 0.2"/>
    <axis xyz="1 0 0"/>
    <limit effort="1000.0" lower="-0.78" upper="0.78" velocity="0.5"/>
  </joint>
  <link name="zero_link_1_0">
    <visual>
      <geometry>
        <cylinder length="0" radius="0"/>
      </geometry>
      <origin rpy="0 0 0" xyz="0 0 0"/>
    </visual>
  </link>
  <joint name="balljoint_1_1" type="revolute">
    <parent link="zero_link_1_0"/>
    <child link="zero_link_1_1"/>
    <origin rpy="0 0 0" xyz="0 0 0"/>
    <axis xyz="0 1 0"/>
    <limit effort="1000.0" lower="-0.78" upper="0.78" velocity="0.5"/>
  </joint>
  <link name="zero_link_1_1">
    <visual>
      <geometry>
        <cylinder length="0" radius="0"/>
      </geometry>
      <origin rpy="0 0 0" xyz="0 0 0"/>
    </visual>
  </link>
  <joint name="balljoint_1_2" type="revolute">
    <parent link="zero_link_1_1"/>
    <child link="link_1"/>
    <origin rpy="0 0 0" xyz="0 0 0"/>
    <axis xyz="0 0 1"/>
    <limit effort="1000.0" lower="-0.78" upper="0.78" velocity="0.5"/>
  </joint>
  <!-- <link name = "link_snake">
    <inertial>
      <origin rpy="0 0 0" xyz="0 -0.016 0.161"/>
      <mass value="7.7"/>
      <inertia ixx="0.06718763333333333" ixy="0" ixz="0" iyy="0.06653056666666667" iyz="0" izz="0.0006570666666666666"/>
    </inertial>
    <visual>
      <geometry>
        <mesh filename="package://medsnake_sim/meshModel/snake_part.STL" scale="0.001 0.001 0.001"/>
      </geometry>
      <origin rpy="0 0 0" xyz="-0.022 -0.02 -0.02"/>
      <material name="yellow"/>
    </visual>
  </link> -->
  <!-- <link name="test">
    <visual>
      <geometry>
        <cylinder length="0.3" radius="0.02" />
      </geometry>
      <origin rpy="0 0 0" xyz="0 0 0.15" />
      <material name="yellow" />
    </visual>
  </link>

  <joint name="balljoint_1" type="revolute">
    <parent link="test" />
    <child link="test2" />
    <origin rpy="0 0 0" xyz="0 0 0.3" />
    <axis xyz="1 0 0" />
    <limit effort="1000.0" lower="-0.548" upper="0.548" velocity="0.5" />
  </joint>
  <joint name="balljoint_2" type="revolute">
    <parent link="test2" />
    <child link="test3" />
    <origin rpy="0 0 0" xyz="0 0 0" />
    <axis xyz="0 1 0" />
    <limit effort="1000.0" lower="-0.548" upper="0.548" velocity="0.5" />
  </joint>
  <joint name="balljoint_3" type="revolute">
    <parent link="test3" />
    <child link="test4" />
    <origin rpy="0 0 0" xyz="0 0 0" />
    <axis xyz="0 0 1" />
    <limit effort="1000.0" lower="-0.548" upper="0.548" velocity="0.5" />
  </joint>
  <joint name="balljoint_4" type="revolute">
    <parent link="test4" />
    <child link="test5" />
    <origin rpy="0 0 0" xyz="0 0 0.1" />
    <axis xyz="1 0 0" />
    <limit effort="1000.0" lower="-0.548" upper="0.548" velocity="0.5" />
  </joint>
  <joint name="balljoint_5" type="revolute">
    <parent link="test5" />
    <child link="test6" />
    <origin rpy="0 0 0" xyz="0 0 0" />
    <axis xyz="0 1 0" />
    <limit effort="1000.0" lower="-0.548" upper="0.548" velocity="0.5" />
  </joint>
  <joint name="balljoint_6" type="revolute">
    <parent link="test6" />
    <child link="test7" />
    <origin rpy="0 0 0" xyz="0 0 0" />
    <axis xyz="0 0 1" />
    <limit effort="1000.0" lower="-0.548" upper="0.548" velocity="0.5" />
  </joint>
  <link name="test2">
    <inertial>
      <origin rpy="0 0 0" xyz="0 0 0" />
      <mass value="7.7" />
      <inertia ixx="0.06718763333333333" ixy="0" ixz="0" iyy="0.06653056666666667" iyz="0" izz="0.0006570666666666666" />
    </inertial>
    <visual>
      <geometry>
        <cylinder length="0" radius="0" />
      </geometry>
      <origin rpy="0 0 0" xyz="0 0 0" />
      <material name="yellow" />
    </visual>
  </link>
  <link name="test3">
    <inertial>
      <origin rpy="0 0 0" xyz="0 0 0" />
      <mass value="7.7" />
      <inertia ixx="0.06718763333333333" ixy="0" ixz="0" iyy="0.06653056666666667" iyz="0" izz="0.0006570666666666666" />
    </inertial>
    <visual>
      <geometry>
        <cylinder length="0" radius="0" />
      </geometry>
      <origin rpy="0 0 0" xyz="0 0 0" />
      <material name="yellow" />
    </visual>
  </link>
  <link name="test4">
    <inertial>
      <origin rpy="0 0 0" xyz="0 0 0" />
      <mass value="7.7" />
      <inertia ixx="0.06718763333333333" ixy="0" ixz="0" iyy="0.06653056666666667" iyz="0" izz="0.0006570666666666666" />
    </inertial>
    <visual>
      <geometry>
        <cylinder length="0.1" radius="0.02" />
      </geometry>
      <origin rpy="0 0 0" xyz="0 0 0.05" />
      <material name="yellow" />
    </visual>
  </link>
  <link name="test5">
    <inertial>
      <origin rpy="0 0 0" xyz="0 0 0" />
      <mass value="7.7" />
      <inertia ixx="0.06718763333333333" ixy="0" ixz="0" iyy="0.06653056666666667" iyz="0" izz="0.0006570666666666666" />
    </inertial>
    <visual>
      <geometry>
        <cylinder length="0" radius="0" />
      </geometry>
      <origin rpy="0 0 0" xyz="0 0 0" />
      <material name="yellow" />
    </visual>
  </link>
  <link name="test6">
    <inertial>
      <origin rpy="0 0 0" xyz="0 0 0" />
      <mass value="7.7" />
      <inertia ixx="0.06718763333333333" ixy="0" ixz="0" iyy="0.06653056666666667" iyz="0" izz="0.0006570666666666666" />
    </inertial>
    <visual>
      <geometry>
        <cylinder length="0" radius="0" />
      </geometry>
      <origin rpy="0 0 0" xyz="0 0 0" />
      <material name="yellow" />
    </visual>
  </link>
  <link name="test7">
    <inertial>
      <origin rpy="0 0 0" xyz="0 0 0" />
      <mass value="7.7" />
      <inertia ixx="0.06718763333333333" ixy="0" ixz="0" iyy="0.06653056666666667" iyz="0" izz="0.0006570666666666666" />
    </inertial>
    <visual>
      <geometry>
        <cylinder length="0.1" radius="0.02" />
      </geometry>
      <origin rpy="0 0 0" xyz="0 0 0.05" />
      <material name="yellow" />
    </visual>
  </link> -->
</robot>

